Workbook

Sheet 2024
A2: EUTHANASIAS 2024
A3: FECHA | B3: ESTABLO | C3: CABALLO | D3: MICROCHIP | E3: RAZON
A4: 2-ENERO-2024 | B4: GARCIA | C4: LA PATRONA G | D4: 981020033087979
A5: 3-ENERO-2024 | B5: AQUINO | C5: PROSPECT PROJECT | D5: 981020021527287 | E5: END STAGE ARTHRITIS RF FETLOCK
A6: 4-ENERO-2024 | B6: GCA | C6: CONVINCENTE | D6: 981020031383586 | E6: FRACTURA RODILLA IZQUIERDA
A7: 5-ENERO-2024 | B7: LANCARA | C7: BEEMERS BOY | D7: 981020037573957 | E7: CONDYLAR FRACTURE
A8: 5-ENERO-2024 | B8: FANTASTIC 4 | C8: MENTIROSO | D8: 981020025169692 | E8: SEVERE DJD BOTH ANKLES / SEVERE LIGAMENT INJURY WITH BROKEN SPLINT BONES
A9: 5-ENERO-2024 | B9: MARQUEZ | C9: PEQUENO ADRIAN | D9: 985170002956976 | E9: FRACTURA DE LA CANA IZQUIERDA DELANTERA
A10: 7-ENERO-2024 | B10: SANCHEZ | C10: EVERY DAY CAPI | D10: 981020019171896
A11: 8-ENERO-2024 | B11: MAJESTUOSO (1,000) | C11: VALECAT | D11: 981020021436120
A12: 11-ENERO-2024 | B12: DC | C12: GREY HEART | D12: 981020037656742 | E12: COMMINUTED SLAB FRACTURE OF RIGHT CIII
A13: 12-ENERO-2024 | B13: ERV | C13: MILAGRITO | D13: 981020037383964 | E13: SEPTIC JOINT RIGHT INTERCARPAL
A14: 12-ENERO-2024 | B14: TORRES PAGAN | C14: CONCEPTUS | D14: 981020033552035 | E14: LAMINITIS
A15: 12-ENERO-2024 | B15: WILLIAM ALVEIRO | C15: BANDIDO | D15: NO TIENE | E15: COLICO
A16: 13-ENERO-2024 | B16: LEGACY | C16: KUMANDRA | D16: 981020031375259 | E16: TENDONITIS SEVERA IZQUIERDA DELANTERA
A17: 13-ENERO-2024 | B17: VILLA REAL | C17: ORGULLOSO | D17: 981020033580400 | E17: FRACTURA AMBAS RODILLAS
A18: 14-ENERO-2024 | B18: ERA RACING | C18: MRS KITCHEN | D18: 981020049676107 | E18: FRACTURA HOMBRO IZQUIERDO
A19: 15-ENERO-2024 | B19: THREE KINGS | C19: ST. ANDRES | D19: 981020035160579
A20: 16-ENERO-2024 | B20: L & D THOROUGHBRED | C20: JAZHARA | D20: 981020035720582 | E20: FRACTURA RODILLA DERECHA
A21: 16-ENERO-2024 | B21: LEGACY | C21: DIXIE CANDY | D21: 981020023518625 | E21: FETLOCK BREAKDOWN INJURY BOTH HIND LEGS.
A22: 19-ENERO-2024 | B22: EL DURAKO | C22: EL BUFFALO | D22: 981020035728387 | E22: Fractura rodilla derecha
A23: 19-ENERO-2024 | B23: KEANCA | C23: MY MAGICAL MAN | D23: 985141001301755 | E23: Artritis severa menudillo izquierdo delantero
A24: 20-ENERO-2024 | B24: ALEXIS CARTAGENA | C24: NEPTUNO | D24: N/A (PRIVADO) | E24: Colico
A25: 22-ENERO-2024 | B25: SML | C25: MY WAY OR ELSE | D25: 981020025188398 | E25: Artritis septica (menudillo derecho delantero)
A26: 22-ENERO-2024 | B26: SJ FARM | C26: NOICATTIRO | D26: 981020031326852 | E26: Right front ankle fracture sesamoid. Laminitis of both hands can't walk or train.
A27: 22-ENERO-2024 | B27: SACO E SAL | C27: REGINA ISABEL | D27: 981020033095231 | E27: Fractura rodilla derecha
A28: 26-ENERO-2024 | B28: BROTHERS | C28: PRESENTADOR | D28: 981020027766947 | E28: Laminitis cronica.
A29: 31-ENERO-2024 | B29: JF | C29: MISTER PILOT | D29: 981020033142559 | E29: Fractura Húmero
A30: 2-FEBRERO-2024 | B30: N Y N | C30: UNIFIED CONQUEST | D30: 981020031364199 | E30: HERIDA PARTE POSTERIOR DEL MENUDILLO, CUARTILLA IZQUIERDA DELANTERA INCLUYENDO LA VAINA DEL TENDON
A31: 5-FEBRERO-2024 | B31: ANGEL CALDERON | C31: CYBERICA | D31: 981020023488884 | E31: ARTRITIS SEVERA EN MENUDILLO DELANTERO.
A32: 7-FEBRERO-2024 | B32: ROCHE KALIL | C32: ERNESTO M | D32: 0A01787568 | E32: COLICO & POOR BODY CONDITION.
A33: 7-FEBRERO-2024 | B33: YORAM | C33: MINERA | D33: 981020033612721 | E33: ARTRITIS SEVERA DERECHO DELANTERO
A34: 8-FEBRERO-2024 | B34: CARMEN ANITA | C34: INDIAN SENSE | D34: 981020023252791 | E34: ARTRITIS SEVERA
A35: 9-FEBRERO-2024 | B35: LIDIEL | C35: EL MONITOR | D35: 981020023271767 | E35: Artritis severa menudillo izquierdo delantero
A36: 12-FEBRERO-2024 | B36: V.G.O | C36: IAN P.R. | D36: 981020039665310 | E36: FRACTURA AMBAS RODILLAS
A37: 13-FEBRERO-2024 | B37: CENTRAL | C37: EL TIO BOLO | D37: 981020045089585 | E37: ARTRITIS SEVERA RODILLA IZQUIERDA
A38: 13-FEBRERO-2024 | B38: DIVINO NINO | C38: EL MAPA | D38: 981020033105565 | E38: TENDON BREAKDOWN RF LEG
A39: 13-FEBRERO-2024 | B39: DESAFIO | C39: SPEEDY D | D39: 981020037644126 | E39: FRACTURA SESAMOIDE PATA DERECHA DELANTERA
A40: 13-FEBRERO-2024 | B40: ALAMO | C40: CLEMENTE BORICUA | D40: 981020031381064 | E40: FRACTURA AMBAS RODILLAS
A41: 14-FEBRERO-2024 | B41: SILENT | C41: RECOMPENSADO | D41: 981020033097903 | E41: Artritis severa rodilla derecha
...

Sheet 2025
A1: EUTHANASIAS 2025
A2: FECHA | B2: ESTABLO | C2: CABALLO | D2: MICROCHIP | E2: RAZON
A3: 9-ENERO-2025 | B3: 47 ROSES OF P.R. | C3: PERICIA | D3: 981020031381027 | E3: Multiples fracturas rodilla derecha
A4: 14-ENERO-2025 | B4: DMA | C4: MATTER OF TRUST | D4: 981020037363425 | E4: LF MC III lateral condylar fracture
A5: 21-ENERO-2025 | B5: JAC | C5: VENEZUELA FIRST | D5: 981020033086157 | E5: Artritis severa menudillo izquierdo delantero
A6: 24-ENERO-2025 | B6: TORRES PAGAN | C6: AFIRMADO | D6: 981020045134542 | E6: L Dorsal MC III cortical fracture
A7: 26-ENERO-2025 | B7: LOS LEE | C7: POSEIDON | D7: 981020045154834 | E7: Rodilla derecha- Slab FX
A8: 27-ENERO-2025 | B8: CINCO HERMANOS | C8: FIESTA BRAVA | D8: 981020039627868 | E8: Fractura en ambas rodillas
A9: 28-ENERO-2025 | B9: SILOE | C9: COBRADOR | D9: 990000004659991 | E9: Fractura/artritis rodilla izquierda
A10: 31-ENERO-2025 | B10: LA 010 | C10: CARICIA DEL CIELO | D10: 981020037655891 | E10: Colic last night + Severe DJD Knee + LF ankle fracture (sesamoids). (Referido PRHOA)
A11: 4-FEBRERO-2025 | B11: ANTONIO E ISABEL | C11: MUNAY | D11: 981020045096215 | E11: R Knee distal radius big fracture, proximal intermediate fx. (Referido PRHOA)
A12: 4-FEBRERO-2025 | B12: DU-RA-KO | C12: MAURICIO | D12: 981020039318212 | E12: Fractura rodilla izquierda.
A13: 10-FEBRERO-2025 | B13: ADORNO | C13: AMAIA MY LOVE | D13: 981020035165913 | E13: Artritis en ambos menudillos delanteros.
A14: 11-FEBRERO-2025 | B14: M SANTIAGO | C14: ARABIAN HEART | D14: 981020045133028 | E14: Diagnóstico previo de problemas neurológicos. Hoy recumbente incapaz de pararse.
... A37: 10-MARZO-2025 | B37: RM | C37: SMALL GUN | D37: 981020037356076 | E37: Chronic tendinitis on both front limbs
A38: 12-MARZO-2025 | B38: CTA | C38: CRUISES CREEK | D38: 0A02461076 | E38: Cólico. Colon desplazado.
A39: 14-MARZO-2025 | B39: R RACING | C39: DON ICO T | D39: 981020033766894 | E39: Bilateral pleuropneumonia.
A40: 15-MARZO-2025 | B40: GCA | C40: K MENA | D40: 981020023226058 | E40: Fracture LF P-1
A41: 17-MARZO-2025 | B41: HISTORY | C41: DYLAN THE GREAT | D41: 981020033772308 | E41: R Carpal severe OA secundary to chronic chip fractures. (Referido PRHOA)
A42: 18-MARZO-2025 | B42: GUILLERMO BERRIOS | C42: AMAZING TRIP | D42: 981020031332003 | E42: RF ankle severe DJD with no joint space. Splint bones fractures with collateral fragments. (Referido PRHOA)
A43: 22-MARZO-2025 | B43: RAFANIL | C43: CENTAURO | D43: 981020031358339 | E43: Laminitis LF hoof
A44: 28-MARZO-2025 | B44: NUEVA GENERACIÓN | C44: ANUALIZADA | D44: 981020031385780 | E44: C-3 Slab fracture (Referido PRHOA)
A45: 7-ABRIL-2025 | B45: JR | C45: DIME RUBÉN M | D45: 981020045155381 | E45: Múltiples fracturas en ambas rodillas.
A46: 8-ABRIL-2025 | B46: L&D THOROUGHBRED | C46: DAMA DE HIERRO | D46: 981020051143307 | E46: Fractura hombro derecho. (Se fue a la pista)
A47: 8-ABRIL-2025 | B47: R RACING | C47: PATRIÓTICA | D47: 981020037355507 | E47: Artritis crónica ambos menudillos delanteros. Fractura sagital L C-3. Artritis séptica L RC.
A48: 8-ABRIL-2025 | B48: ORIÓN | C48: EL INTRÉPIDO | D48: 981020045124783 | E48: Fractura rodilla izquierda (C-3 Slab).
A49: 22-ABRIL-2025 | B49: CHAD | C49: MI BOTICARIA | D49: 981020037339477 | E49: Near complete tear in medial pastern bundle of the DDFT. (Referido PRHOA)
A50: 25-ABRIL-2025 | B50: PRECISE STAR | C50: JESS'S STRIDE | D50: 981020025195230 | E50: Cólico.
... A64: 26-MAYO-2025 | B64: R RACING | C64: LOLITO | D64: 981020037350886 | E64: L C3 Slab fracture.
A65: 26-MAYO-2025 | B65: HACIENDA EL SUEÑO | C65: CHIQUILIN | D65: N/A | E65: Tétano.
A66: 29-MAYO-2025 | B66: JI DIAMOND | C66: MAMI OLGA | D66: 981020031358368 | E66: Bilateral front limbs suspensory desmitis in subluxation of pastern joints.
A67: 29-MAYO-2025 | B67: CARMEN ANITA | C67: CRIOLLITO | D67: 981020023533123 | E67: Cólico (enteritis).
A68: 30-MAYO-2025 | B68: DMA | C68: JUST CROWN | D68: 981020031349176 | E68: Artritis menudillo izquierdo delantero.
A69: 30-MAYO-2025 | B69: LA 010 | C69: SIMÉTRICO | D69: 981020037640759 | E69: Referido PRHOA
A70: 30-MAYO-2025 | B70: INVICTUS | C70: TIZ THE SKY | D70: 981020033568849 | E70: Mid-body fracture of medial sesamoid + apical fracture of lateral sesamoid.
A71: 1-JUNIO-2025 | B71: GRAN POLLO | C71: GRAN LEXY | D71: 981020037297457 | E71: Fractura sesamoide derecho delantero.
A72: 7-JUNIO-2025 | B72: DENIAN | C72: AMERICAN SUNSHINE | D72: 981020037320306 | E72: Tendinitis cronica pata derecha delantera.
A73: 8-JUNIO-2025 | B73: JCM | C73: HOLY SECRET | D73: 981020023691827 | E73: RH Condylar Fracture. (Guardia PRHOA. No se utilizó Beuthanasia).
A74: 9-JUNIO-2025 | B74: R RACING | C74: TOMA PUERTORRO | D74: 981020031379310 | E74: Múltiples fracturas en ambas rodillas.
A75: 10-JUNIO-2025 | B75: AYALA | C75: AYALAS | D75: 981020037322464 | E75: Fractura rodilla izquierda.
...

Sheet 2026
A1: EUTHANASIAS 2026
A2: FECHA | B2: ESTABLO | C2: CABALLO | D2: MICROCHIP | E2: RAZON
A3: 2-ENERO-2026 | B3: MA D CO | C3: C R NOMI | D3: 981020037309179 | E3: Severe carpal disease. (Referido PRHOA)
A4: 2-ENERO-2026 | B4: WILLIE | C4: JARAB DE ZAPETE | D4: 981020031389160 | E4: Fractura caña izquierda + múltiples fracturas rodilla derecha. (Referido PRHOA)
A5: 2-ENERO-2026 | B5: V.G.O. | C5: EXCLUSIVA | D5: 981020049702663 | E5: RF Suspensory Desmitis.
A6: 3-ENERO-2026 | B6: PRETTY H@RSE | C6: BLAZZING ARROW | D6: 981020045084422 | E6: RF C-3 Slab fracture. (Referido PRHOA)
A7: 5-ENERO-2026 | B7: G.R.C. | C7: YAHIR | D7: 981020037381563 | E7: LF artritis severa.

Sheet Sheet5
A1: Categoría | B1: Fractura ósea
A2: AVG Starts by year | B2: 9672 | D2: =B2/12 -> 806 | E2: =1000/12 -> 83.333333
B3: Years
B4: 2024 | C4: 2025
A5: Death Horses | B5: 0.54356846 | C5: 0.45643154
B7: 2025 | C7: 2024
A8: Death Horses | B8: 0.46 | C8: 0.54
B24: 2024 | D24: 2025
A25: Months | B25: Death Horses | C25: % Death Diff | D25: Death Horses
A26: Jan | B26: 0.083969466 | D26: 0.054545455
A27: Feb | B27: 0.053435115 | D27: 0.1
A28: Mar | B28: 0.061068702 | D28: 0.081818182
A29: Apr | B29: 0.083969466 | D29: 0.036363636
A30: May | B30: 0.13740458 | D30: 0.072727273
A31: Jun | B31: 0.076335878 | D31: 0.090909091
A32: Jul | B32: 0.15267176 | D32: 0.15454545
A33: Aug | B33: 0.06870229 | D33: 0.090909091
A34: Sep | B34: 0.083969466 | D34: 0.081818182
A35: Oct | B35: 0.045801527 | D35: 0.081818182
A36: Nov | B36: 0.045801527 | D36: 0.090909091
A37: Dec | B37: 0.10687023 | D37: 0.063636364

Sheet Sheet7
A1: Data returned for Count of CABALLO, Otras / No especificada (First 1000 rows).
A3: Range[FECHA] | B3: Range[día] | C3: Range[Mes] | D3: Range[Date] | E3: Range[ESTABLO] | F3: Range[CABALLO] | G3: Range[RAZON] | H3: Range[Categoría] | I3: Range[Tipo de fractura] | J3: Range[Fatal injury] | K3: Range[Date (Month)] | L3: Range[Date (Year)] | M3: Range[Date (Quarter)] | N3: Range[Date (Month Index)]
A4: 12-ENERO-2024 | B4: 12 | C4: ENERO | D4: 45303 | E4: ERV | F4: MILAGRITO | G4: SEPTIC JOINT RIGHT INTERCARPAL | H4: Otras / No especificada | I4: 0 | J4: Fatal injury | K4: Jan | L4: 2024 | M4: Qtr1 | N4: 1
A5: 12-ENERO-2024 | B5: 12 | C5: ENERO | D5: 45303 | E5: TORRES PAGAN | F5: CONCEPTUS | G5: LAMINITIS | H5: Otras / No especificada | I5: 0 | J5: No clasificado | K5: Jan | L5: 2024 | M5: Qtr1 | N5: 1
A6: 12-ENERO-2024 | B6: 12 | C6: ENERO | D6: 45303 | E6: WILLIAM ALVEIRO | F6: BANDIDO | G6: COLICO | H6: Otras / No especificada | I6: 0 | J6: No clasificado | K6: Jan | L6: 2024 | M6: Qtr1 | N6: 1
A7: 16-ENERO-2024 | B7: 16 | C7: ENERO | D7: 45307 | E7: LEGACY | F7: DIXIE CANDY | G7: FETLOCK BREAKDOWN INJURY BOTH HIND LEGS. | H7: Otras / No especificada | I7: 0 | J7: Fatal injury | K7: Jan | L7: 2024 | M7: Qtr1 | N7: 1
A8: 20-ENERO-2024 | B8: 20 | C8: ENERO | D8: 45311 | E8: ALEXIS CARTAGENA | F8: NEPTUNO | G8: COLICO | H8: Otras / No especificada | I8: 0 | J8: No clasificado | K8: Jan | L8: 2024 | M8: Qtr1 | N8: 1
A9: 26-ENERO-2024 | B9: 26 | C9: ENERO | D9: 45317 | E9: BROTHERS | F9: PRESENTADOR | G9: Laminitis cronica. | H9: Otras / No especificada | I9: 0 | J9: No clasificado | K9: Jan | L9: 2024 | M9: Qtr1 | N9: 1
A10: 7-FEBRERO-2024 | B10: 7 | C10: FEBRERO | D10: 45329 | E10: ROCHE KALIL | F10: ERNESTO M | G10: COLICO & POOR BODY CONDITION. | H10: Otras / No especificada | I10: 0 | J10: No clasificado | K10: Feb | L10: 2024 | M10: Qtr1 | N10: 2
A11: 16-FEBRERO-2024 | B11: 16 | C11: FEBRERO | D11: 45338 | E11: RAFANIL | F11: I'M YOUR LUV | G11: Aggressive eye cancer | H11: Otras / No especificada | I11: 0 | J11: No clasificado | K11: Feb | L11: 2024 | M11: Qtr1 | N11: 2
A12: 19-FEBRERO-2024 | B12: 19 | C12: FEBRERO | D12: 45341 | E12: STUD JUNIOR V | F12: DRA. ANA CAROLINA | G12: Tendón desgarrado pata izquierda trasera/ Laminitis pata derecha trasera | H12: Otras / No especificada | I12: 0 | J12: No clasificado | K12: Feb | L12: 2024 | M12: Qtr1 | N12: 2
A13: 23-FEBRERO-2024 | B13: 23 | C13: FEBRERO | D13: 45345 | E13: MANUEL GOMEZ | F13: ARTIFICAL INTELL | G13: Referido Drs. PRHOA. LF Front severe DID Knee and fetlock smooth rest. Cannot train. | H13: Otras / No especificada | I13: 0 | J13: Fatal injury | K13: Feb | L13: 2024 | M13: Qtr1 | N13: 2
A14: 24-FEBRERO-2024 | B14: 24 | C14: FEBRERO | D14: 45346 | E14: ARECIBO | F14: QUALITY STRIKE | G14: Cólico | H14: Otras / No especificada | I14: 0 | J14: No clasificado | K14: Feb | L14: 2024 | M14: Qtr1 | N14: 2
A15: 27-FEBRERO-2024 | B15: 27 | C15: FEBRERO | D15: 45349 | E15: FARO DE LUZ | F15: E.R.V. ENTERPISES | G15: Referido Drs. PRHOA. R Carpus. | H15: Otras / No especificada | I15: 0 | J15: No clasificado | K15: Feb | L15: 2024 | M15: Qtr1 | N15: 2
... A131: 31-DICIEMBRE-2025 | B131: 31 | C131: DICIEMBRE | D131: 46022 | E131: RAMZ | F131: JORGITO L | G131: Chronic diarrea for 5 weeks duration. R hind limb cellulitis. (Referido PRHOA) | H131: Otras / No especificada | I131: 0 | J131: No fatal injury (chronic/medical) | K131: Dec | L131: 2025 | M131: Qtr4 | N131: 12

Sheet Sheet6
A3: Row Labels | B3: Count of CABALLO
A4: Enfermedad degenerativa articular | B4: 57
A5: Fractura ósea | B5: 241
A6: Lesión de ligamentos/tendones | B6: 15
A7: Otras / No especificada
A8: Aggressive eye cancer | B8: 1
A9: Bilateral front fetlock palmar metacarpal disease. Unresolved lameness. (Referido PRHOA) | B9: 1
A10: Bilateral front limb tendinitis | B10: 1
A11: Bilateral front limbs tendinitis/desmitis with excessive dorsiflexion of fetlock joints. | B11: 1
A12: Bilateral laminitis. Fetlock severe OA. (Referido PRHOA) | B12: 1
A13: Bilateral pleuropneumonia. | B13: 1
A14: Breakdown injury both front limbs. Referido PRHOA. | B14: 1
A15: Breakdown injury LF (menudillo izquierdo delantero) | B15: 1
A16: Breakdown injury LF fetlock | B16: 1
A17: Breakdown injury LF Knee. (Guardia PRHOA-PM) | B17: 1
A18: Breakdown injury LF leg with tissue necrosy. Referido Dr. García Blanco. | B18: 1
A19: Catastrophic breakdown injury left fetlock | B19: 1
... A122: Grand Total | B122: 441

Sheet Sheet8
A1: Categoría | B1: Fractura ósea
A3: Count of CABALLO | B3: Column Labels
A4: Row Labels | B4: 2024 | C4: 2025 | D4: Grand Total
A5: Jan
A6: Caña / Cannon bone | B6: 1 | D6: 1
A7: Condylar | B7: 1 | C7: 1 | D7: 2
A8: No especificado | B8: 2 | C8: 1 | D8: 3
A9: Rodilla / Carpal | B9: 5 | C9: 3 | D9: 8
A10: Sesamoideo | B10: 1 | C10: 1 | D10: 2
A11: Slab | B11: 1 | D11: 1
A12: Jan Total | B12: 11 | C12: 6 | D12: 17
A13: Feb
A14: No especificado | C14: 7 | D14: 7
A15: Rodilla / Carpal | B15: 4 | C15: 2 | D15: 6
A16: Sesamoideo | B16: 3 | C16: 1 | D16: 4
A17: Slab | C17: 1 | D17: 1
A18: Feb Total | B18: 7 | C18: 11 | D18: 18
A19: Mar
A20: Caña / Cannon bone | B20: 3 | D20: 3
A21: No especificado | B21: 1 | C21: 3 | D21: 4
A22: Rodilla / Carpal | B22: 2 | C22: 2 | D22: 4
A23: Sesamoideo | B23: 1 | C23: 1 | D23: 2
A24: Slab | B24: 1 | C24: 2 | D24: 3
A25: Splint | C25: 1 | D25: 1
A26: Mar Total | B26: 8 | C26: 9 | D26: 17
A27: Apr
A28: Caña / Cannon bone | B28: 1 | D28: 1
A29: No especificado | B29: 1 | C29: 2 | D29: 3
A30: Rodilla / Carpal | B30: 7 | C30: 1 | D30: 8
A31: Sesamoideo | B31: 1 | D31: 1
A32: Slab | B32: 1 | C32: 1 | D32: 2
A33: Apr Total | B33: 11 | C33: 4 | D33: 15
A34: May
A35: Caña / Cannon bone | B35: 2 | C35: 1 | D35: 3
A36: No especificado | B36: 6 | C36: 2 | D36: 8
A37: Rodilla / Carpal | B37: 7 | C37: 1 | D37: 8
A38: Sesamoideo | B38: 3 | C38: 2 | D38: 5
A39: Slab | C39: 2 | D39: 2
A40: May Total | B40: 18 | C40: 8 | D40: 26
A41: Jun
...

Sheet Toda la data
A1: FECHA | B1: día | C1: Mes | D1: Date | E1: ESTABLO | F1: CABALLO | G1: RAZON | H1: Categoría | I1: Tipo de fractura | J1: Fatal injury
A2: 2-ENERO-2024 | B2: =LEFT(A2,FIND("-",A2)-1) -> 2 | C2: =MID(A2,FIND("-",A2)+1,FIND("-",A2,FIND("-",A2)+1)-FIND("-",A2)-1) -> ENERO | D2: 45293 | E2: GARCIA | F2: LA PATRONA G | H2: =_xlfn.XLOOKUP($G2,RazónMuerte!$A:$A,RazónMuerte!B:B,"",0) -> 0 | I2: =_xlfn.XLOOKUP($G2,RazónMuerte!$A:$A,RazónMuerte!C:C,"",0) -> 0 | J2: =_xlfn.XLOOKUP($G2,RazónMuerte!$A:$A,RazónMuerte!D:D,"",0) -> 0
A3: 3-ENERO-2024 | B3: =LEFT(A3,FIND("-",A3)-1) -> 3 | C3: =MID(A3,FIND("-",A3)+1,FIND("-",A3,FIND("-",A3)+1)-FIND("-",A3)-1) -> ENERO | D3: 45294 | E3: AQUINO | F3: PROSPECT PROJECT | G3: END STAGE ARTHRITIS RF FETLOCK | H3: =_xlfn.XLOOKUP($G3,RazónMuerte!$A:$A,RazónMuerte!B:B,"",0) -> Enfermedad degenerativa articular | I3: =_xlfn.XLOOKUP($G3,RazónMuerte!$A:$A,RazónMuerte!C:C,"",0) -> 0 | J3: =_xlfn.XLOOKUP($G3,RazónMuerte!$A:$A,RazónMuerte!D:D,"",0) -> Fatal injury
A4: 4-ENERO-2024 | B4: =LEFT(A4,FIND("-",A4)-1) -> 4 | C4: =MID(A4,FIND("-",A4)+1,FIND("-",A4,FIND("-",A4)+1)-FIND("-",A4)-1) -> ENERO | D4: 45295 | E4: GCA | F4: CONVINCENTE | G4: FRACTURA RODILLA IZQUIERDA | H4: =_xlfn.XLOOKUP($G4,RazónMuerte!$A:$A,RazónMuerte!B:B,"",0) -> Fractura ósea | I4: =_xlfn.XLOOKUP($G4,RazónMuerte!$A:$A,RazónMuerte!C:C,"",0) -> Rodilla / Carpal | J4: =_xlfn.XLOOKUP($G4,RazónMuerte!$A:$A,RazónMuerte!D:D,"",0) -> Fatal injury
A5: 5-ENERO-2024 | B5: =LEFT(A5,FIND("-",A5)-1) -> 5 | C5: =MID(A5,FIND("-",A5)+1,FIND("-",A5,FIND("-",A5)+1)-FIND("-",A5)-1) -> ENERO | D5: 45296 | E5: LANCARA | F5: BEEMERS BOY | G5: CONDYLAR FRACTURE | H5: =_xlfn.XLOOKUP($G5,RazónMuerte!$A:$A,RazónMuerte!B:B,"",0) -> Fractura ósea | I5: =_xlfn.XLOOKUP($G5,RazónMuerte!$A:$A,RazónMuerte!C:C,"",0) -> Condylar | J5: =_xlfn.XLOOKUP($G5,RazónMuerte!$A:$A,RazónMuerte!D:D,"",0) -> Fatal injury
A6: 5-ENERO-2024 | B6: =LEFT(A6,FIND("-",A6)-1) -> 5 | C6: =MID(A6,FIND("-",A6)+1,FIND("-",A6,FIND("-",A6)+1)-FIND("-",A6)-1) -> ENERO | D6: 45296 | E6: FANTASTIC 4 | F6: MENTIROSO | G6: SEVERE DJD BOTH ANKLES / SEVERE LIGAMENT INJURY WITH BROKEN SPLINT BONES | H6: =_xlfn.XLOOKUP($G6,RazónMuerte!$A:$A,RazónMuerte!B:B,"",0) -> Enfermedad degenerativa articular | I6: =_xlfn.XLOOKUP($G6,RazónMuerte!$A:$A,RazónMuerte!C:C,"",0) -> 0 | J6: =_xlfn.XLOOKUP($G6,RazónMuerte!$A:$A,RazónMuerte!D:D,"",0) -> No fatal injury (chronic/medical)
A7: 5-ENERO-2024 | B7: =LEFT(A7,FIND("-",A7)-1) -> 5 | C7: =MID(A7,FIND("-",A7)+1,FIND("-",A7,FIND("-",A7)+1)-FIND("-",A7)-1) -> ENERO | D7: 45296 | E7: MARQUEZ | F7: PEQUENO ADRIAN | G7: FRACTURA DE LA CANA IZQUIERDA DELANTERA | H7: =_xlfn.XLOOKUP($G7,RazónMuerte!$A:$A,RazónMuerte!B:B,"",0) -> Fractura ósea | I7: =_xlfn.XLOOKUP($G7,RazónMuerte!$A:$A,RazónMuerte!C:C,"",0) -> Caña / Cannon bone | J7: =_xlfn.XLOOKUP($G7,RazónMuerte!$A:$A,RazónMuerte!D:D,"",0) -> Fatal injury
A8: 7-ENERO-2024 | B8: =LEFT(A8,FIND("-",A8)-1) -> 7 | C8: =MID(A8,FIND("-",A8)+1,FIND("-",A8,FIND("-",A8)+1)-FIND("-",A8)-1) -> ENERO | D8: 45298 | E8: SANCHEZ | F8: EVERY DAY CAPI | H8: =_xlfn.XLOOKUP($G8,RazónMuerte!$A:$A,RazónMuerte!B:B,"",0) -> 0 | I8: =_xlfn.XLOOKUP($G8,RazónMuerte!$A:$A,RazónMuerte!C:C,"",0) -> 0 | J8: =_xlfn.XLOOKUP($G8,RazónMuerte!$A:$A,RazónMuerte!D:D,"",0) -> 0
A9: 8-ENERO-2024 | B9: =LEFT(A9,FIND("-",A9)-1) -> 8 | C9: =MID(A9,FIND("-",A9)+1,FIND("-",A9,FIND("-",A9)+1)-FIND("-",A9)-1) -> ENERO | D9: 45299 | E9: MAJESTUOSO (1,000) | F9: VALECAT | H9: =_xlfn.XLOOKUP($G9,RazónMuerte!$A:$A,RazónMuerte!B:B,"",0) -> 0 | I9: =_xlfn.XLOOKUP($G9,RazónMuerte!$A:$A,RazónMuerte!C:C,"",0) -> 0 | J9: =_xlfn.XLOOKUP($G9,RazónMuerte!$A:$A,RazónMuerte!D:D,"",0) -> 0
A10: 11-ENERO-2024 | B10: =LEFT(A10,FIND("-",A10)-1) -> 11 | C10: =MID(A10,FIND("-",A10)+1,FIND("-",A10,FIND("-",A10)+1)-FIND("-",A10)-1) -> ENERO | D10: 45302 | E10: DC | F10: GREY HEART | G10: COMMINUTED SLAB FRACTURE OF RIGHT CIII | H10: =_xlfn.XLOOKUP($G10,RazónMuerte!$A:$A,RazónMuerte!B:B,"",0) -> Fractura ósea | I10: =_xlfn.XLOOKUP($G10,RazónMuerte!$A:$A,RazónMuerte!C:C,"",0) -> Slab | J10: =_xlfn.XLOOKUP($G10,RazónMuerte!$A:$A,RazónMuerte!D:D,"",0) -> Fatal injury
A11: 12-ENERO-2024 | B11: =LEFT(A11,FIND("-",A11)-1) -> 12 | C11: =MID(A11,FIND("-",A11)+1,FIND("-",A11,FIND("-",A11)+1)-FIND("-",A11)-1) -> ENERO | D11: 45303 | E11: ERV | F11: MILAGRITO | G11: SEPTIC JOINT RIGHT INTERCARPAL | H11: =_xlfn.XLOOKUP($G11,RazónMuerte!$A:$A,RazónMuerte!B:B,"",0) -> Otras / No especificada | I11: =_xlfn.XLOOKUP($G11,RazónMuerte!$A:$A,RazónMuerte!C:C,"",0) -> 0 | J11: =_xlfn.XLOOKUP($G11,RazónMuerte!$A:$A,RazónMuerte!D:D,"",0) -> Fatal injury
A12: 12-ENERO-2024 | B12: =LEFT(A12,FIND("-",A12)-1) -> 12 | C12: =MID(A12,FIND("-",A12)+1,FIND("-",A12,FIND("-",A12)+1)-FIND("-",A12)-1) -> ENERO | D12: 45303 | E12: TORRES PAGAN | F12: CONCEPTUS | G12: LAMINITIS | H12: =_xlfn.XLOOKUP($G12,RazónMuerte!$A:$A,RazónMuerte!B:B,"",0) -> Otras / No especificada | I12: =_xlfn.XLOOKUP($G12,RazónMuerte!$A:$A,RazónMuerte!C:C,"",0) -> 0 | J12: =_xlfn.XLOOKUP($G12,RazónMuerte!$A:$A,RazónMuerte!D:D,"",0) -> No clasificado
A13: 12-ENERO-2024 | B13: =LEFT(A13,FIND("-",A13)-1) -> 12 | C13: =MID(A13,FIND("-",A13)+1,FIND("-",A13,FIND("-",A13)+1)-FIND("-",A13)-1) -> ENERO | D13: 45303 | E13: WILLIAM ALVEIRO | F13: BANDIDO | G13: COLICO | H13: =_xlfn.XLOOKUP($G13,RazónMuerte!$A:$A,RazónMuerte!B:B,"",0) -> Otras / No especificada | I13: =_xlfn.XLOOKUP($G13,RazónMuerte!$A:$A,RazónMuerte!C:C,"",0) -> 0 | J13: =_xlfn.XLOOKUP($G13,RazónMuerte!$A:$A,RazónMuerte!D:D,"",0) -> No clasificado
A14: 13-ENERO-2024 | B14: =LEFT(A14,FIND("-",A14)-1) -> 13 | C14: =MID(A14,FIND("-",A14)+1,FIND("-",A14,FIND("-",A14)+1)-FIND("-",A14)-1) -> ENERO | D14: 45304 | E14: LEGACY | F14: KUMANDRA | G14: TENDONITIS SEVERA IZQUIERDA DELANTERA | H14: =_xlfn.XLOOKUP($G14,RazónMuerte!$A:$A,RazónMuerte!B:B,"",0) -> Lesión de ligamentos/tendones | I14: =_xlfn.XLOOKUP($G14,RazónMuerte!$A:$A,RazónMuerte!C:C,"",0) -> 0 | J14: =_xlfn.XLOOKUP($G14,RazónMuerte!$A:$A,RazónMuerte!D:D,"",0) -> No clasificado
A15: 13-ENERO-2024 | B15: =LEFT(A15,FIND("-",A15)-1) -> 13 | C15: =MID(A15,FIND("-",A15)+1,FIND("-",A15,FIND("-",A15)+1)-FIND("-",A15)-1) -> ENERO | D15: 45304 | E15: VILLA REAL | F15: ORGULLOSO | G15: FRACTURA AMBAS RODILLAS | H15: =_xlfn.XLOOKUP($G15,RazónMuerte!$A:$A,RazónMuerte!B:B,"",0) -> Fractura ósea | I15: =_xlfn.XLOOKUP($G15,RazónMuerte!$A:$A,RazónMuerte!C:C,"",0) -> Rodilla / Carpal | J15: =_xlfn.XLOOKUP($G15,RazónMuerte!$A:$A,RazónMuerte!D:D,"",0) -> Fatal injury
A16: 14-ENERO-2024 | B16: =LEFT(A16,FIND("-",A16)-1) -> 14 | C16: =MID(A16,FIND("-",A16)+1,FIND("-",A16,FIND("-",A16)+1)-FIND("-",A16)-1) -> ENERO | D16: 45305 | E16: ERA RACING | F16: MRS KITCHEN | G16: FRACTURA HOMBRO IZQUIERDO | H16: =_xlfn.XLOOKUP($G16,RazónMuerte!$A:$A,RazónMuerte!B:B,"",0) -> Fractura ósea | I16: =_xlfn.XLOOKUP($G16,RazónMuerte!$A:$A,RazónMuerte!C:C,"",0) -> No especificado | J16: =_xlfn.XLOOKUP($G16,RazónMuerte!$A:$A,RazónMuerte!D:D,"",0) -> Fatal injury
A17: 15-ENERO-2024 | B17: =LEFT(A17,FIND("-",A17)-1) -> 15 | C17: =MID(A17,FIND("-",A17)+1,FIND("-",A17,FIND("-",A17)+1)-FIND("-",A17)-1) -> ENERO | D17: 45306 | E17: THREE KINGS | F17: ST. ANDRES | H17: =_xlfn.XLOOKUP($G17,RazónMuerte!$A:$A,RazónMuerte!B:B,"",0) -> 0 | I17: =_xlfn.XLOOKUP($G17,RazónMuerte!$A:$A,RazónMuerte!C:C,"",0) -> 0 | J17: =_xlfn.XLOOKUP($G17,RazónMuerte!$A:$A,RazónMuerte!D:D,"",0) -> 0
A18: 16-ENERO-2024 | B18: =LEFT(A18,FIND("-",A18)-1) -> 16 | C18: =MID(A18,FIND("-",A18)+1,FIND("-",A18,FIND("-",A18)+1)-FIND("-",A18)-1) -> ENERO | D18: 45307 | E18: L & D THOROUGHBRED | F18: JAZHARA | G18: FRACTURA RODILLA DERECHA | H18: =_xlfn.XLOOKUP($G18,RazónMuerte!$A:$A,RazónMuerte!B:B,"",0) -> Fractura ósea | I18: =_xlfn.XLOOKUP($G18,RazónMuerte!$A:$A,RazónMuerte!C:C,"",0) -> Rodilla / Carpal | J18: =_xlfn.XLOOKUP($G18,RazónMuerte!$A:$A,RazónMuerte!D:D,"",0) -> Fatal injury
A19: 16-ENERO-2024 | B19: =LEFT(A19,FIND("-",A19)-1) -> 16 | C19: =MID(A19,FIND("-",A19)+1,FIND("-",A19,FIND("-",A19)+1)-FIND("-",A19)-1) -> ENERO | D19: 45307 | E19: LEGACY | F19: DIXIE CANDY | G19: FETLOCK BREAKDOWN INJURY BOTH HIND LEGS. | H19: =_xlfn.XLOOKUP($G19,RazónMuerte!$A:$A,RazónMuerte!B:B,"",0) -> Otras / No especificada | I19: =_xlfn.XLOOKUP($G19,RazónMuerte!$A:$A,RazónMuerte!C:C,"",0) -> 0 | J19: =_xlfn.XLOOKUP($G19,RazónMuerte!$A:$A,RazónMuerte!D:D,"",0) -> Fatal injury
A20: 19-ENERO-2024 | B20: =LEFT(A20,FIND("-",A20)-1) -> 19 | C20: =MID(A20,FIND("-",A20)+1,FIND("-",A20,FIND("-",A20)+1)-FIND("-",A20)-1) -> ENERO | D20: 45310 | E20: EL DURAKO | F20: EL BUFFALO | G20: Fractura rodilla derecha | H20: =_xlfn.XLOOKUP($G20,RazónMuerte!$A:$A,RazónMuerte!B:B,"",0) -> Fractura ósea | I20: =_xlfn.XLOOKUP($G20,RazónMuerte!$A:$A,RazónMuerte!C:C,"",0) -> Rodilla / Carpal | J20: =_xlfn.XLOOKUP($G20,RazónMuerte!$A:$A,RazónMuerte!D:D,"",0) -> Fatal injury
A21: 19-ENERO-2024 | B21: =LEFT(A21,FIND("-",A21)-1) -> 19 | C21: =MID(A21,FIND("-",A21)+1,FIND("-",A21,FIND("-",A21)+1)-FIND("-",A21)-1) -> ENERO | D21: 45310 | E21: KEANCA | F21: MY MAGICAL MAN | G21: Artritis severa menudillo izquierdo delantero | H21: =_xlfn.XLOOKUP($G21,RazónMuerte!$A:$A,RazónMuerte!B:B,"",0) -> Enfermedad degenerativa articular | I21: =_xlfn.XLOOKUP($G21,RazónMuerte!$A:$A,RazónMuerte!C:C,"",0) -> 0 | J21: =_xlfn.XLOOKUP($G21,RazónMuerte!$A:$A,RazónMuerte!D:D,"",0) -> No fatal injury (chronic/medical)
A22: 20-ENERO-2024 | B22: =LEFT(A22,FIND("-",A22)-1) -> 20 | C22: =MID(A22,FIND("-",A22)+1,FIND("-",A22,FIND("-",A22)+1)-FIND("-",A22)-1) -> ENERO | D22: 45311 | E22: ALEXIS CARTAGENA | F22: NEPTUNO | G22: Colico | H22: =_xlfn.XLOOKUP($G22,RazónMuerte!$A:$A,RazónMuerte!B:B,"",0) -> Otras / No especificada | I22: =_xlfn.XLOOKUP($G22,RazónMuerte!$A:$A,RazónMuerte!C:C,"",0) -> 0 | J22: =_xlfn.XLOOKUP($G22,RazónMuerte!$A:$A,RazónMuerte!D:D,"",0) -> No clasificado
A23: 22-ENERO-2024 | B23: =LEFT(A23,FIND("-",A23)-1) -> 22 | C23: =MID(A23,FIND("-",A23)+1,FIND("-",A23,FIND("-",A23)+1)-FIND("-",A23)-1) -> ENERO | D23: 45313 | E23: SML | F23: MY WAY OR ELSE | G23: Artritis septica (menudillo derecho delantero) | H23: =_xlfn.XLOOKUP($G23,RazónMuerte!$A:$A,RazónMuerte!B:B,"",0) -> Enfermedad degenerativa articular | I23: =_xlfn.XLOOKUP($G23,RazónMuerte!$A:$A,RazónMuerte!C:C,"",0) -> 0 | J23: =_xlfn.XLOOKUP($G23,RazónMuerte!$A:$A,RazónMuerte!D:D,"",0) -> No fatal injury (chronic/medical)
A24: 22-ENERO-2024 | B24: =LEFT(A24,FIND("-",A24)-1) -> 22 | C24: =MID(A24,FIND("-",A24)+1,FIND("-",A24,FIND("-",A24)+1)-FIND("-",A24)-1) -> ENERO | D24: 45313 | E24: SJ FARM | F24: NOICATTIRO | G24: Right front ankle fracture sesamoid. Laminitis of both hands can't walk or train. | H24: =_xlfn.XLOOKUP($G24,RazónMuerte!$A:$A,RazónMuerte!B:B,"",0) -> Fractura ósea | I24: =_xlfn.XLOOKUP($G24,RazónMuerte!$A:$A,RazónMuerte!C:C,"",0) -> Sesamoideo | J24: =_xlfn.XLOOKUP($G24,RazónMuerte!$A:$A,RazónMuerte!D:D,"",0) -> Fatal injury
A25: 22-ENERO-2024 | B25: =LEFT(A25,FIND("-",A25)-1) -> 22 | C25: =MID(A25,FIND("-",A25)+1,FIND("-",A25,FIND("-",A25)+1)-FIND("-",A25)-1) -> ENERO | D25: 45313 | E25: SACO E SAL | F25: REGINA ISABEL | G25: Fractura rodilla derecha | H25: =_xlfn.XLOOKUP($G25,RazónMuerte!$A:$A,RazónMuerte!B:B,"",0) -> Fractura ósea | I25: =_xlfn.XLOOKUP($G25,RazónMuerte!$A:$A,RazónMuerte!C:C,"",0) -> Rodilla / Carpal | J25: =_xlfn.XLOOKUP($G25,RazónMuerte!$A:$A,RazónMuerte!D:D,"",0) -> Fatal injury
A26: 26-ENERO-2024 | B26: =LEFT(A26,FIND("-",A26)-1) -> 26 | C26: =MID(A26,FIND("-",A26)+1,FIND("-",A26,FIND("-",A26)+1)-FIND("-",A26)-1) -> ENERO | D26: 45317 | E26: BROTHERS | F26: PRESENTADOR | G26: Laminitis cronica. | H26: =_xlfn.XLOOKUP($G26,RazónMuerte!$A:$A,RazónMuerte!B:B,"",0) -> Otras / No especificada | I26: =_xlfn.XLOOKUP($G26,RazónMuerte!$A:$A,RazónMuerte!C:C,"",0) -> 0 | J26: =_xlfn.XLOOKUP($G26,RazónMuerte!$A:$A,RazónMuerte!D:D,"",0) -> No clasificado
A27: 31-ENERO-2024 | B27: =LEFT(A27,FIND("-",A27)-1) -> 31 | C27: =MID(A27,FIND("-",A27)+1,FIND("-",A27,FIND("-",A27)+1)-FIND("-",A27)-1) -> ENERO | D27: 45322 | E27: JF | F27: MISTER PILOT | G27: Fractura Húmero | H27: =_xlfn.XLOOKUP($G27,RazónMuerte!$A:$A,RazónMuerte!B:B,"",0) -> Fractura ósea | I27: =_xlfn.XLOOKUP($G27,RazónMuerte!$A:$A,RazónMuerte!C:C,"",0) -> No especificado | J27: =_xlfn.XLOOKUP($G27,RazónMuerte!$A:$A,RazónMuerte!D:D,"",0) -> Fatal injury
A28: 2-FEBRERO-2024 | B28: =LEFT(A28,FIND("-",A28)-1) -> 2 | C28: =MID(A28,FIND("-",A28)+1,FIND("-",A28,FIND("-",A28)+1)-FIND("-",A28)-1) -> FEBRERO | D28: 45324 | E28: N Y N | F28: UNIFIED CONQUEST | G28: HERIDA PARTE POSTERIOR DEL MENUDILLO, CUARTILLA IZQUIERDA DELANTERA INCLUYENDO LA VAINA DEL TENDON | H28: =_xlfn.XLOOKUP($G28,RazónMuerte!$A:$A,RazónMuerte!B:B,"",0) -> Lesión de ligamentos/tendones | I28: =_xlfn.XLOOKUP($G28,RazónMuerte!$A:$A,RazónMuerte!C:C,"",0) -> 0 | J28: =_xlfn.XLOOKUP($G28,RazónMuerte!$A:$A,RazónMuerte!D:D,"",0) -> No clasificado
A29: 5-FEBRERO-2024 | B29: =LEFT(A29,FIND("-",A29)-1) -> 5 | C29: =MID(A29,FIND("-",A29)+1,FIND("-",A29,FIND("-",A29)+1)-FIND("-",A29)-1) -> FEBRERO | D29: 45327 | E29: ANGEL CALDERON | F29: CYBERICA | G29: ARTRITIS SEVERA EN MENUDILLO DELANTERO. | H29: =_xlfn.XLOOKUP($G29,RazónMuerte!$A:$A,RazónMuerte!B:B,"",0) -> Enfermedad degenerativa articular | I29: =_xlfn.XLOOKUP($G29,RazónMuerte!$A:$A,RazónMuerte!C:C,"",0) -> 0 | J29: =_xlfn.XLOOKUP($G29,RazónMuerte!$A:$A,RazónMuerte!D:D,"",0) -> No fatal injury (chronic/medical)
... A359: 3-AGOSTO-2025 | B359: =LEFT(A359,FIND("-",A359)-1) -> 3 | C359: =MID(A359,FIND("-",A359)+1,FIND("-",A359,FIND("-",A359)+1)-FIND("-",A359)-1) -> AGOSTO | D359: 45872 | E359: M SANTIAGO | F359: ARABIAN MOON | G359: Fractura rodilla izquierda (Guardia PRHOA) | H359: =_xlfn.XLOOKUP($G359,RazónMuerte!$A:$A,RazónMuerte!B:B,"",0) -> Fractura ósea | I359: =_xlfn.XLOOKUP($G359,RazónMuerte!$A:$A,RazónMuerte!C:C,"",0) -> Rodilla / Carpal | J359: =_xlfn.XLOOKUP($G359,RazónMuerte!$A:$A,RazónMuerte!D:D,"",0) -> Fatal injury
A360: 3-AGOSTO-2025 | B360: =LEFT(A360,FIND("-",A360)-1) -> 3 | C360: =MID(A360,FIND("-",A360)+1,FIND("-",A360,FIND("-",A360)+1)-FIND("-",A360)-1) -> AGOSTO | D360: 45872 | E360: JORMALY | F360: LA NIETA E JORGI C | H360: =_xlfn.XLOOKUP($G360,RazónMuerte!$A:$A,RazónMuerte!B:B,"",0) -> 0 | I360: =_xlfn.XLOOKUP($G360,RazónMuerte!$A:$A,RazónMuerte!C:C,"",0) -> 0 | J360: =_xlfn.XLOOKUP($G360,RazónMuerte!$A:$A,RazónMuerte!D:D,"",0) -> 0
A361: 4-AGOSTO-2025 | B361: =LEFT(A361,FIND("-",A361)-1) -> 4 | C361: =MID(A361,FIND("-",A361)+1,FIND("-",A361,FIND("-",A361)+1)-FIND("-",A361)-1) -> AGOSTO | D361: 45873 | E361: SANTA RITA | F361: YERAI | G361: Slab fracture L Knee | H361: =_xlfn.XLOOKUP($G361,RazónMuerte!$A:$A,RazónMuerte!B:B,"",0) -> Fractura ósea | I361: =_xlfn.XLOOKUP($G361,RazónMuerte!$A:$A,RazónMuerte!C:C,"",0) -> Slab | J361: =_xlfn.XLOOKUP($G361,RazónMuerte!$A:$A,RazónMuerte!D:D,"",0) -> Fatal injury
A362: 4-AGOSTO-2025 | B362: =LEFT(A362,FIND("-",A362)-1) -> 4 | C362: =MID(A362,FIND("-",A362)+1,FIND("-",A362,FIND("-",A362)+1)-FIND("-",A362)-1) -> AGOSTO | D362: 45873 | E362: TARRATS NACC | F362: DIAMOND THE GOAT | G362: RF base sesamoid fracture | H362: =_xlfn.XLOOKUP($G362,RazónMuerte!$A:$A,RazónMuerte!B:B,"",0) -> Fractura ósea | I362: =_xlfn.XLOOKUP($G362,RazónMuerte!$A:$A,RazónMuerte!C:C,"",0) -> Sesamoideo | J362: =_xlfn.XLOOKUP($G362,RazónMuerte!$A:$A,RazónMuerte!D:D,"",0) -> Fatal injury
A363: 4-AGOSTO-2025 | B363: =LEFT(A363,FIND("-",A363)-1) -> 4 | C363: =MID(A363,FIND("-",A363)+1,FIND("-",A363,FIND("-",A363)+1)-FIND("-",A363)-1) -> AGOSTO | D363: 45873 | E363: VILLA REAL | F363: PERFECCIONISTA | G363: L C3 Slab fracture. | H363: =_xlfn.XLOOKUP($G363,RazónMuerte!$A:$A,RazónMuerte!B:B,"",0) -> Fractura ósea | I363: =_xlfn.XLOOKUP($G363,RazónMuerte!$A:$A,RazónMuerte!C:C,"",0) -> Slab | J363: =_xlfn.XLOOKUP($G363,RazónMuerte!$A:$A,RazónMuerte!D:D,"",0) -> Fatal injury
A364: 9-AGOSTO-2025 | B364: =LEFT(A364,FIND("-",A364)-1) -> 9 | C364: =MID(A364,FIND("-",A364)+1,FIND("-",A364,FIND("-",A364)+1)-FIND("-",A364)-1) -> AGOSTO | D364: 45878 | E364: SONATA | F364: VOLATILE DANCER | G364: LF Breakdown injury. | H364: =_xlfn.XLOOKUP($G364,RazónMuerte!$A:$A,RazónMuerte!B:B,"",0) -> Otras / No especificada | I364: =_xlfn.XLOOKUP($G364,RazónMuerte!$A:$A,RazónMuerte!C:C,"",0) -> 0 | J364: =_xlfn.XLOOKUP($G364,RazónMuerte!$A:$A,RazónMuerte!D:D,"",0) -> No clasificado
A365: 11-AGOSTO-2025 | B365: =LEFT(A365,FIND("-",A365)-1) -> 11 | C365: =MID(A365,FIND("-",A365)+1,FIND("-",A365,FIND("-",A365)+1)-FIND("-",A365)-1) -> AGOSTO | D365: 45880 | E365: POCOS PERO FIRMES | F365: ANFITRIONA | G365: Fractura rodilla derecha. | H365: =_xlfn.XLOOKUP($G365,RazónMuerte!$A:$A,RazónMuerte!B:B,"",0) -> Fractura ósea | I365: =_xlfn.XLOOKUP($G365,RazónMuerte!$A:$A,RazónMuerte!C:C,"",0) -> Rodilla / Carpal | J365: =_xlfn.XLOOKUP($G365,RazónMuerte!$A:$A,RazónMuerte!D:D,"",0) -> Fatal injury
A366: 13-AGOSTO-2025 | B366: =LEFT(A366,FIND("-",A366)-1) -> 13 | C366: =MID(A366,FIND("-",A366)+1,FIND("-",A366,FIND("-",A366)+1)-FIND("-",A366)-1) -> AGOSTO | D366: 45882 | E366: JI DIAMOND | F366: PESCADOR DE SUEÑOS | G366: Fractura rodilla derecha. | H366: =_xlfn.XLOOKUP($G366,RazónMuerte!$A:$A,RazónMuerte!B:B,"",0) -> Fractura ósea | I366: =_xlfn.XLOOKUP($G366,RazónMuerte!$A:$A,RazónMuerte!C:C,"",0) -> Rodilla / Carpal | J366: =_xlfn.XLOOKUP($G366,RazónMuerte!$A:$A,RazónMuerte!D:D,"",0) -> Fatal injury
A367: 13-AGOSTO-2025 | B367: =LEFT(A367,FIND("-",A367)-1) -> 13 | C367: =MID(A367,FIND("-",A367)+1,FIND("-",A367,FIND("-",A367)+1)-FIND("-",A367)-1) -> AGOSTO | D367: 45882 | E367: JI DIAMOND | F367: EL GALLOLFO | G367: Laminitis en ambas manos/Múltiples fracturas en ambas rodillas L>R. | H367: =_xlfn.XLOOKUP($G367,RazónMuerte!$A:$A,RazónMuerte!B:B,"",0) -> Fractura ósea | I367: =_xlfn.XLOOKUP($G367,RazónMuerte!$A:$A,RazónMuerte!C:C,"",0) -> Rodilla / Carpal | J367: =_xlfn.XLOOKUP($G367,RazónMuerte!$A:$A,RazónMuerte!D:D,"",0) -> Fatal injury
A368: 13-AGOSTO-2025 | B368: =LEFT(A368,FIND("-",A368)-1) -> 13 | C368: =MID(A368,FIND("-",A368)+1,FIND("-",A368,FIND("-",A368)+1)-FIND("-",A368)-1) -> AGOSTO | D368: 45882 | E368: JI DIAMOND | F368: BLACK SILK | G368: Fractura rodilla izquierda. | H368: =_xlfn.XLOOKUP($G368,RazónMuerte!$A:$A,RazónMuerte!B:B,"",0) -> Fractura ósea | I368: =_xlfn.XLOOKUP($G368,RazónMuerte!$A:$A,RazónMuerte!C:C,"",0) -> Rodilla / Carpal | J368: =_xlfn.XLOOKUP($G368,RazónMuerte!$A:$A,RazónMuerte!D:D,"",0) -> Fatal injury
A369: 14-AGOSTO-2025 | B369: =LEFT(A369,FIND("-",A369)-1) -> 14 | C369: =MID(A369,FIND("-",A369)+1,FIND("-",A369,FIND("-",A369)+1)-FIND("-",A369)-1) -> AGOSTO | D369: 45883 | E369: QUINTANA | F369: HARD TEN | G369: Artritis severa menudillo derecho delantero. | H369: =_xlfn.XLOOKUP($G369,RazónMuerte!$A:$A,RazónMuerte!B:B,"",0) -> Enfermedad degenerativa articular | I369: =_xlfn.XLOOKUP($G369,RazónMuerte!$A:$A,RazónMuerte!C:C,"",0) -> 0 | J369: =_xlfn.XLOOKUP($G369,RazónMuerte!$A:$A,RazónMuerte!D:D,"",0) -> No fatal injury (chronic/medical)
...

Sheet 2024 data
A1: FECHA | B1: día | C1: Mes | D1: Last Race Date (desde Equibase) | E1: Death Date | F1: ESTABLO | G1: Horas transcurridas | H1: CABALLO | I1: RAZON | J1: Categoría | K1: Tipo de fractura | L1: Fatal injury | M1: Registrado/Compitió?
A2: 2-ENERO-2024 | B2: =LEFT(A2,FIND("-",A2)-1) -> 2 | C2: =MID(A2,FIND("-",A2)+1,FIND("-",A2,FIND("-",A2)+1)-FIND("-",A2)-1) -> ENERO | D2: 45282 | E2: 45293 | F2: GARCIA | G2: =(E2-D2)*24 -> 264 | H2: LA PATRONA G | J2: =_xlfn.XLOOKUP($I2,RazónMuerte!$A:$A,RazónMuerte!B:B,"",0) -> 0 | K2: =_xlfn.XLOOKUP($I2,RazónMuerte!$A:$A,RazónMuerte!C:C,"",0) -> 0 | L2: =_xlfn.XLOOKUP($I2,RazónMuerte!$A:$A,RazónMuerte!D:D,"",0) -> 0
A3: 3-ENERO-2024 | B3: =LEFT(A3,FIND("-",A3)-1) -> 3 | C3: =MID(A3,FIND("-",A3)+1,FIND("-",A3,FIND("-",A3)+1)-FIND("-",A3)-1) -> ENERO | D3: 45106 | E3: 45294 | F3: AQUINO | G3: =(E3-D3)*24 -> 4512 | H3: PROSPECT PROJECT | I3: END STAGE ARTHRITIS RF FETLOCK | J3: =_xlfn.XLOOKUP($I3,RazónMuerte!$A:$A,RazónMuerte!B:B,"",0) -> Enfermedad degenerativa articular | K3: =_xlfn.XLOOKUP($I3,RazónMuerte!$A:$A,RazónMuerte!C:C,"",0) -> 0 | L3: =_xlfn.XLOOKUP($I3,RazónMuerte!$A:$A,RazónMuerte!D:D,"",0) -> Fatal injury
A4: 4-ENERO-2024 | B4: =LEFT(A4,FIND("-",A4)-1) -> 4 | C4: =MID(A4,FIND("-",A4)+1,FIND("-",A4,FIND("-",A4)+1)-FIND("-",A4)-1) -> ENERO | D4: 45221 | E4: 45295 | F4: GCA | G4: =(E4-D4)*24 -> 1776 | H4: CONVINCENTE | I4: FRACTURA RODILLA IZQUIERDA | J4: =_xlfn.XLOOKUP($I4,RazónMuerte!$A:$A,RazónMuerte!B:B,"",0) -> Fractura ósea | K4: =_xlfn.XLOOKUP($I4,RazónMuerte!$A:$A,RazónMuerte!C:C,"",0) -> Rodilla / Carpal | L4: =_xlfn.XLOOKUP($I4,RazónMuerte!$A:$A,RazónMuerte!D:D,"",0) -> Fatal injury
A5: 5-ENERO-2024 | B5: =LEFT(A5,FIND("-",A5)-1) -> 5 | C5: =MID(A5,FIND("-",A5)+1,FIND("-",A5,FIND("-",A5)+1)-FIND("-",A5)-1) -> ENERO | D5: 45274 | E5: 45296 | F5: LANCARA | G5: =(E5-D5)*24 -> 528 | H5: BEEMERS BOY | I5: CONDYLAR FRACTURE | J5: =_xlfn.XLOOKUP($I5,RazónMuerte!$A:$A,RazónMuerte!B:B,"",0) -> Fractura ósea | K5: =_xlfn.XLOOKUP($I5,RazónMuerte!$A:$A,RazónMuerte!C:C,"",0) -> Condylar | L5: =_xlfn.XLOOKUP($I5,RazónMuerte!$A:$A,RazónMuerte!D:D,"",0) -> Fatal injury
A6: 5-ENERO-2024 | B6: =LEFT(A6,FIND("-",A6)-1) -> 5 | C6: =MID(A6,FIND("-",A6)+1,FIND("-",A6,FIND("-",A6)+1)-FIND("-",A6)-1) -> ENERO | D6: 45277 | E6: 45296 | F6: FANTASTIC 4 | G6: =(E6-D6)*24 -> 456 | H6: MENTIROSO | I6: SEVERE DJD BOTH ANKLES / SEVERE LIGAMENT INJURY WITH BROKEN SPLINT BONES | J6: =_xlfn.XLOOKUP($I6,RazónMuerte!$A:$A,RazónMuerte!B:B,"",0) -> Enfermedad degenerativa articular | K6: =_xlfn.XLOOKUP($I6,RazónMuerte!$A:$A,RazónMuerte!C:C,"",0) -> 0 | L6: =_xlfn.XLOOKUP($I6,RazónMuerte!$A:$A,RazónMuerte!D:D,"",0) -> No fatal injury (chronic/medical)
A7: 5-ENERO-2024 | B7: =LEFT(A7,FIND("-",A7)-1) -> 5 | C7: =MID(A7,FIND("-",A7)+1,FIND("-",A7,FIND("-",A7)+1)-FIND("-",A7)-1) -> ENERO | D7: 45282 | E7: 45296 | F7: MARQUEZ | G7: =(E7-D7)*24 -> 336 | H7: PEQUENO ADRIAN | I7: FRACTURA DE LA CANA IZQUIERDA DELANTERA | J7: =_xlfn.XLOOKUP($I7,RazónMuerte!$A:$A,RazónMuerte!B:B,"",0) -> Fractura ósea | K7: =_xlfn.XLOOKUP($I7,RazónMuerte!$A:$A,RazónMuerte!C:C,"",0) -> Caña / Cannon bone | L7: =_xlfn.XLOOKUP($I7,RazónMuerte!$A:$A,RazónMuerte!D:D,"",0) -> Fatal injury
A8: 7-ENERO-2024 | B8: =LEFT(A8,FIND("-",A8)-1) -> 7 | C8: =MID(A8,FIND("-",A8)+1,FIND("-",A8,FIND("-",A8)+1)-FIND("-",A8)-1) -> ENERO | D8: 45298 | E8: 45298 | F8: SANCHEZ | G8: =(E8-D8)*24 -> 0 | H8: EVERY DAY CAPI | J8: =_xlfn.XLOOKUP($I8,RazónMuerte!$A:$A,RazónMuerte!B:B,"",0) -> 0 | K8: =_xlfn.XLOOKUP($I8,RazónMuerte!$A:$A,RazónMuerte!C:C,"",0) -> 0 | L8: =_xlfn.XLOOKUP($I8,RazónMuerte!$A:$A,RazónMuerte!D:D,"",0) -> 0
A9: 8-ENERO-2024 | B9: =LEFT(A9,FIND("-",A9)-1) -> 8 | C9: =MID(A9,FIND("-",A9)+1,FIND("-",A9,FIND("-",A9)+1)-FIND("-",A9)-1) -> ENERO | D9: 45277 | E9: 45299 | F9: MAJESTUOSO (1,000) | G9: =(E9-D9)*24 -> 528 | H9: VALECAT | J9: =_xlfn.XLOOKUP($I9,RazónMuerte!$A:$A,RazónMuerte!B:B,"",0) -> 0 | K9: =_xlfn.XLOOKUP($I9,RazónMuerte!$A:$A,RazónMuerte!C:C,"",0) -> 0 | L9: =_xlfn.XLOOKUP($I9,RazónMuerte!$A:$A,RazónMuerte!D:D,"",0) -> 0
A10: 11-ENERO-2024 | B10: =LEFT(A10,FIND("-",A10)-1) -> 11 | C10: =MID(A10,FIND("-",A10)+1,FIND("-",A10,FIND("-",A10)+1)-FIND("-",A10)-1) -> ENERO | E10: 45302 | F10: DC | G10: =(E10-D10)*24 -> 1087248 | H10: GREY HEART | I10: COMMINUTED SLAB FRACTURE OF RIGHT CIII | J10: =_xlfn.XLOOKUP($I10,RazónMuerte!$A:$A,RazónMuerte!B:B,"",0) -> Fractura ósea | K10: =_xlfn.XLOOKUP($I10,RazónMuerte!$A:$A,RazónMuerte!C:C,"",0) -> Slab | L10: =_xlfn.XLOOKUP($I10,RazónMuerte!$A:$A,RazónMuerte!D:D,"",0) -> Fatal injury
A11: 12-ENERO-2024 | B11: =LEFT(A11,FIND("-",A11)-1) -> 12 | C11: =MID(A11,FIND("-",A11)+1,FIND("-",A11,FIND("-",A11)+1)-FIND("-",A11)-1) -> ENERO | E11: 45303 | F11: ERV | G11: =(E11-D11)*24 -> 1087272 | H11: MILAGRITO | I11: SEPTIC JOINT RIGHT INTERCARPAL | J11: =_xlfn.XLOOKUP($I11,RazónMuerte!$A:$A,RazónMuerte!B:B,"",0) -> Otras / No especificada | K11: =_xlfn.XLOOKUP($I11,RazónMuerte!$A:$A,RazónMuerte!C:C,"",0) -> 0 | L11: =_xlfn.XLOOKUP($I11,RazónMuerte!$A:$A,RazónMuerte!D:D,"",0) -> Fatal injury
A12: 12-ENERO-2024 | B12: =LEFT(A12,FIND("-",A12)-1) -> 12 | C12: =MID(A12,FIND("-",A12)+1,FIND("-",A12,FIND("-",A12)+1)-FIND("-",A12)-1) -> ENERO | D12: 45275 | E12: 45303 | F12: TORRES PAGAN | G12: =(E12-D12)*24 -> 672 | H12: CONCEPTUS | I12: LAMINITIS | J12: =_xlfn.XLOOKUP($I12,RazónMuerte!$A:$A,RazónMuerte!B:B,"",0) -> Otras / No especificada | K12: =_xlfn.XLOOKUP($I12,RazónMuerte!$A:$A,RazónMuerte!C:C,"",0) -> 0 | L12: =_xlfn.XLOOKUP($I12,RazónMuerte!$A:$A,RazónMuerte!D:D,"",0) -> No clasificado
A13: 12-ENERO-2024 | B13: =LEFT(A13,FIND("-",A13)-1) -> 12 | C13: =MID(A13,FIND("-",A13)+1,FIND("-",A13,FIND("-",A13)+1)-FIND("-",A13)-1) -> ENERO | E13: 45303 | F13: WILLIAM ALVEIRO | G13: =(E13-D13)*24 -> 1087272 | H13: BANDIDO | I13: COLICO | J13: =_xlfn.XLOOKUP($I13,RazónMuerte!$A:$A,RazónMuerte!B:B,"",0) -> Otras / No especificada | K13: =_xlfn.XLOOKUP($I13,RazónMuerte!$A:$A,RazónMuerte!C:C,"",0) -> 0 | L13: =_xlfn.XLOOKUP($I13,RazónMuerte!$A:$A,RazónMuerte!D:D,"",0) -> No clasificado
A14: 13-ENERO-2024 | B14: =LEFT(A14,FIND("-",A14)-1) -> 13 | C14: =MID(A14,FIND("-",A14)+1,FIND("-",A14,FIND("-",A14)+1)-FIND("-",A14)-1) -> ENERO | D14: 44946 | E14: 45304 | F14: LEGACY | G14: =(E14-D14)*24 -> 8592 | H14: KUMANDRA | I14: TENDONITIS SEVERA IZQUIERDA DELANTERA | J14: =_xlfn.XLOOKUP($I14,RazónMuerte!$A:$A,RazónMuerte!B:B,"",0) -> Lesión de ligamentos/tendones | K14: =_xlfn.XLOOKUP($I14,RazónMuerte!$A:$A,RazónMuerte!C:C,"",0) -> 0 | L14: =_xlfn.XLOOKUP($I14,RazónMuerte!$A:$A,RazónMuerte!D:D,"",0) -> No clasificado
A15: 13-ENERO-2024 | B15: =LEFT(A15,FIND("-",A15)-1) -> 13 | C15: =MID(A15,FIND("-",A15)+1,FIND("-",A15,FIND("-",A15)+1)-FIND("-",A15)-1) -> ENERO | D15: 45296 | E15: 45304 | F15: VILLA REAL | G15: =(E15-D15)*24 -> 192 | H15: ORGULLOSO | I15: FRACTURA AMBAS RODILLAS | J15: =_xlfn.XLOOKUP($I15,RazónMuerte!$A:$A,RazónMuerte!B:B,"",0) -> Fractura ósea | K15: =_xlfn.XLOOKUP($I15,RazónMuerte!$A:$A,RazónMuerte!C:C,"",0) -> Rodilla / Carpal | L15: =_xlfn.XLOOKUP($I15,RazónMuerte!$A:$A,RazónMuerte!D:D,"",0) -> Fatal injury
A16: 14-ENERO-2024 | B16: =LEFT(A16,FIND("-",A16)-1) -> 14 | C16: =MID(A16,FIND("-",A16)+1,FIND("-",A16,FIND("-",A16)+1)-FIND("-",A16)-1) -> ENERO | E16: 45305 | F16: ERA RACING | G16: =(E16-D16)*24 -> 1087320 | H16: MRS KITCHEN | I16: FRACTURA HOMBRO IZQUIERDO | J16: =_xlfn.XLOOKUP($I16,RazónMuerte!$A:$A,RazónMuerte!B:B,"",0) -> Fractura ósea | K16: =_xlfn.XLOOKUP($I16,RazónMuerte!$A:$A,RazónMuerte!C:C,"",0) -> No especificado | L16: =_xlfn.XLOOKUP($I16,RazónMuerte!$A:$A,RazónMuerte!D:D,"",0) -> Fatal injury
A17: 15-ENERO-2024 | B17: =LEFT(A17,FIND("-",A17)-1) -> 15 | C17: =MID(A17,FIND("-",A17)+1,FIND("-",A17,FIND("-",A17)+1)-FIND("-",A17)-1) -> ENERO | D17: 45305 | E17: 45306 | F17: THREE KINGS | G17: =(E17-D17)*24 -> 24 | H17: ST. ANDRES | J17: =_xlfn.XLOOKUP($I17,RazónMuerte!$A:$A,RazónMuerte!B:B,"",0) -> 0 | K17: =_xlfn.XLOOKUP($I17,RazónMuerte!$A:$A,RazónMuerte!C:C,"",0) -> 0 | L17: =_xlfn.XLOOKUP($I17,RazónMuerte!$A:$A,RazónMuerte!D:D,"",0) -> 0
A18: 16-ENERO-2024 | B18: =LEFT(A18,FIND("-",A18)-1) -> 16 | C18: =MID(A18,FIND("-",A18)+1,FIND("-",A18,FIND("-",A18)+1)-FIND("-",A18)-1) -> ENERO | D18: 45306 | E18: 45307 | F18: L & D THOROUGHBRED | G18: =(E18-D18)*24 -> 24 | H18: JAZHARA | I18: FRACTURA RODILLA DERECHA | J18: =_xlfn.XLOOKUP($I18,RazónMuerte!$A:$A,RazónMuerte!B:B,"",0) -> Fractura ósea | K18: =_xlfn.XLOOKUP($I18,RazónMuerte!$A:$A,RazónMuerte!C:C,"",0) -> Rodilla / Carpal | L18: =_xlfn.XLOOKUP($I18,RazónMuerte!$A:$A,RazónMuerte!D:D,"",0) -> Fatal injury
A19: 16-ENERO-2024 | B19: =LEFT(A19,FIND("-",A19)-1) -> 16 | C19: =MID(A19,FIND("-",A19)+1,FIND("-",A19,FIND("-",A19)+1)-FIND("-",A19)-1) -> ENERO | D19: 44764 | E19: 45307 | F19: LEGACY | G19: =(E19-D19)*24 -> 13032 | H19: DIXIE CANDY | I19: FETLOCK BREAKDOWN INJURY BOTH HIND LEGS. | J19: =_xlfn.XLOOKUP($I19,RazónMuerte!$A:$A,RazónMuerte!B:B,"",0) -> Otras / No especificada | K19: =_xlfn.XLOOKUP($I19,RazónMuerte!$A:$A,RazónMuerte!C:C,"",0) -> 0 | L19: =_xlfn.XLOOKUP($I19,RazónMuerte!$A:$A,RazónMuerte!D:D,"",0) -> Fatal injury
A20: 19-ENERO-2024 | B20: =LEFT(A20,FIND("-",A20)-1) -> 19 | C20: =MID(A20,FIND("-",A20)+1,FIND("-",A20,FIND("-",A20)+1)-FIND("-",A20)-1) -> ENERO | D20: 45275 | E20: 45310 | F20: EL DURAKO | G20: =(E20-D20)*24 -> 840 | H20: EL BUFFALO | I20: Fractura rodilla derecha | J20: =_xlfn.XLOOKUP($I20,RazónMuerte!$A:$A,RazónMuerte!B:B,"",0) -> Fractura ósea | K20: =_xlfn.XLOOKUP($I20,RazónMuerte!$A:$A,RazónMuerte!C:C,"",0) -> Rodilla / Carpal | L20: =_xlfn.XLOOKUP($I20,RazónMuerte!$A:$A,RazónMuerte!D:D,"",0) -> Fatal injury
A21: 19-ENERO-2024 | B21: =LEFT(A21,FIND("-",A21)-1) -> 19 | C21: =MID(A21,FIND("-",A21)+1,FIND("-",A21,FIND("-",A21)+1)-FIND("-",A21)-1) -> ENERO | D21: 45282 | E21: 45310 | F21: KEANCA | G21: =(E21-D21)*24 -> 672 | H21: MY MAGICAL MAN | I21: Artritis severa menudillo izquierdo delantero | J21: =_xlfn.XLOOKUP($I21,RazónMuerte!$A:$A,RazónMuerte!B:B,"",0) -> Enfermedad degenerativa articular | K21: =_xlfn.XLOOKUP($I21,RazónMuerte!$A:$A,RazónMuerte!C:C,"",0) -> 0 | L21: =_xlfn.XLOOKUP($I21,RazónMuerte!$A:$A,RazónMuerte!D:D,"",0) -> No fatal injury (chronic/medical)
A22: 20-ENERO-2024 | B22: =LEFT(A22,FIND("-",A22)-1) -> 20 | C22: =MID(A22,FIND("-",A22)+1,FIND("-",A22,FIND("-",A22)+1)-FIND("-",A22)-1) -> ENERO | E22: 45311 | F22: ALEXIS CARTAGENA | G22: =(E22-D22)*24 -> 1087464 | H22: NEPTUNO | I22: Colico | J22: =_xlfn.XLOOKUP($I22,RazónMuerte!$A:$A,RazónMuerte!B:B,"",0) -> Otras / No especificada | K22: =_xlfn.XLOOKUP($I22,RazónMuerte!$A:$A,RazónMuerte!C:C,"",0) -> 0 | L22: =_xlfn.XLOOKUP($I22,RazónMuerte!$A:$A,RazónMuerte!D:D,"",0) -> No clasificado
A23: 22-ENERO-2024 | B23: =LEFT(A23,FIND("-",A23)-1) -> 22 | C23: =MID(A23,FIND("-",A23)+1,FIND("-",A23,FIND("-",A23)+1)-FIND("-",A23)-1) -> ENERO | D23: 45240 | E23: 45313 | F23: SML | G23: =(E23-D23)*24 -> 1752 | H23: MY WAY OR ELSE | I23: Artritis septica (menudillo derecho delantero) | J23: =_xlfn.XLOOKUP($I23,RazónMuerte!$A:$A,RazónMuerte!B:B,"",0) -> Enfermedad degenerativa articular | K23: =_xlfn.XLOOKUP($I23,RazónMuerte!$A:$A,RazónMuerte!C:C,"",0) -> 0 | L23: =_xlfn.XLOOKUP($I23,RazónMuerte!$A:$A,RazónMuerte!D:D,"",0) -> No fatal injury (chronic/medical)
A24: 22-ENERO-2024 | B24: =LEFT(A24,FIND("-",A24)-1) -> 22 | C24: =MID(A24,FIND("-",A24)+1,FIND("-",A24,FIND("-",A24)+1)-FIND("-",A24)-1) -> ENERO | E24: 45313 | F24: SJ FARM | G24: =(E24-D24)*24 -> 1087512 | H24: NOICATTIRO | I24: Right front ankle fracture sesamoid. Laminitis of both hands can't walk or train. | J24: =_xlfn.XLOOKUP($I24,RazónMuerte!$A:$A,RazónMuerte!B:B,"",0) -> Fractura ósea | K24: =_xlfn.XLOOKUP($I24,RazónMuerte!$A:$A,RazónMuerte!C:C,"",0) -> Sesamoideo | L24: =_xlfn.XLOOKUP($I24,RazónMuerte!$A:$A,RazónMuerte!D:D,"",0) -> Fatal injury
A25: 22-ENERO-2024 | B25: =LEFT(A25,FIND("-",A25)-1) -> 22 | C25: =MID(A25,FIND("-",A25)+1,FIND("-",A25,FIND("-",A25)+1)-FIND("-",A25)-1) -> ENERO | D25: 45311 | E25: 45313 | F25: SACO E SAL | G25: =(E25-D25)*24 -> 48 | H25: REGINA ISABEL | I25: Fractura rodilla derecha | J25: =_xlfn.XLOOKUP($I25,RazónMuerte!$A:$A,RazónMuerte!B:B,"",0) -> Fractura ósea | K25: =_xlfn.XLOOKUP($I25,RazónMuerte!$A:$A,RazónMuerte!C:C,"",0) -> Rodilla / Carpal | L25: =_xlfn.XLOOKUP($I25,RazónMuerte!$A:$A,RazónMuerte!D:D,"",0) -> Fatal injury
A26: 26-ENERO-2024 | B26: =LEFT(A26,FIND("-",A26)-1) -> 26 | C26: =MID(A26,FIND("-",A26)+1,FIND("-",A26,FIND("-",A26)+1)-FIND("-",A26)-1) -> ENERO | D26: 45142 | E26: 45317 | F26: BROTHERS | G26: =(E26-D26)*24 -> 4200 | H26: PRESENTADOR | I26: Laminitis cronica. | J26: =_xlfn.XLOOKUP($I26,RazónMuerte!$A:$A,RazónMuerte!B:B,"",0) -> Otras / No especificada | K26: =_xlfn.XLOOKUP($I26,RazónMuerte!$A:$A,RazónMuerte!C:C,"",0) -> 0 | L26: =_xlfn.XLOOKUP($I26,RazónMuerte!$A:$A,RazónMuerte!D:D,"",0) -> No clasificado
A27: 31-ENERO-2024 | B27: =LEFT(A27,FIND("-",A27)-1) -> 31 | C27: =MID(A27,FIND("-",A27)+1,FIND("-",A27,FIND("-",A27)+1)-FIND("-",A27)-1) -> ENERO | D27: 45038 | E27: 45322 | F27: JF | G27: =(E27-D27)*24 -> 6816 | H27: MISTER PILOT | I27: Fractura Húmero | J27: =_xlfn.XLOOKUP($I27,RazónMuerte!$A:$A,RazónMuerte!B:B,"",0) -> Fractura ósea | K27: =_xlfn.XLOOKUP($I27,RazónMuerte!$A:$A,RazónMuerte!C:C,"",0) -> No especificado | L27: =_xlfn.XLOOKUP($I27,RazónMuerte!$A:$A,RazónMuerte!D:D,"",0) -> Fatal injury
A28: 2-FEBRERO-2024 | B28: =LEFT(A28,FIND("-",A28)-1) -> 2 | C28: =MID(A28,FIND("-",A28)+1,FIND("-",A28,FIND("-",A28)+1)-FIND("-",A28)-1) -> FEBRERO | D28: 45323 | E28: 45324 | F28: N Y N | G28: =(E28-D28)*24 -> 24 | H28: UNIFIED CONQUEST | I28: HERIDA PARTE POSTERIOR DEL MENUDILLO, CUARTILLA IZQUIERDA DELANTERA INCLUYENDO LA VAINA DEL TENDON | J28: =_xlfn.XLOOKUP($I28,RazónMuerte!$A:$A,RazónMuerte!B:B,"",0) -> Lesión de ligamentos/tendones | K28: =_xlfn.XLOOKUP($I28,RazónMuerte!$A:$A,RazónMuerte!C:C,"",0) -> 0 | L28: =_xlfn.XLOOKUP($I28,RazónMuerte!$A:$A,RazónMuerte!D:D,"",0) -> No clasificado
A29: 5-FEBRERO-2024 | B29: =LEFT(A29,FIND("-",A29)-1) -> 5 | C29: =MID(A29,FIND("-",A29)+1,FIND("-",A29,FIND("-",A29)+1)-FIND("-",A29)-1) -> FEBRERO | D29: 45130 | E29: 45327 | F29: ANGEL CALDERON | G29: =(E29-D29)*24 -> 4728 | H29: CYBERICA | I29: ARTRITIS SEVERA EN MENUDILLO DELANTERO. | J29: =_xlfn.XLOOKUP($I29,RazónMuerte!$A:$A,RazónMuerte!B:B,"",0) -> Enfermedad degenerativa articular | K29: =_xlfn.XLOOKUP($I29,RazónMuerte!$A:$A,RazónMuerte!C:C,"",0) -> 0 | L29: =_xlfn.XLOOKUP($I29,RazónMuerte!$A:$A,RazónMuerte!D:D,"",0) -> No fatal injury (chronic/medical)
A30: 7-FEBRERO-2024 | B30: =LEFT(A30,FIND("-",A30)-1) -> 7 | C30: =MID(A30,FIND("-",A30)+1,FIND("-",A30,FIND("-",A30)+1)-FIND("-",A30)-1) -> FEBRERO | D30: 45150 | E30: 45329 | F30: ROCHE KALIL | G30: =(E30-D30)*24 -> 4296 | H30: ERNESTO M | I30: COLICO & POOR BODY CONDITION. | J30: =_xlfn.XLOOKUP($I30,RazónMuerte!$A:$A,RazónMuerte!B:B,"",0) -> Otras / No especificada | K30: =_xlfn.XLOOKUP($I30,RazónMuerte!$A:$A,RazónMuerte!C:C,"",0) -> 0 | L30: =_xlfn.XLOOKUP($I30,RazónMuerte!$A:$A,RazónMuerte!D:D,"",0) -> No clasificado
A31: 7-FEBRERO-2024 | B31: =LEFT(A31,FIND("-",A31)-1) -> 7 | C31: =MID(A31,FIND("-",A31)+1,FIND("-",A31,FIND("-",A31)+1)-FIND("-",A31)-1) -> FEBRERO | D31: 45318 | E31: 45329 | F31: YORAM | G31: =(E31-D31)*24 -> 264 | H31: MINERA | I31: ARTRITIS SEVERA DERECHO DELANTERO | J31: =_xlfn.XLOOKUP($I31,RazónMuerte!$A:$A,RazónMuerte!B:B,"",0) -> Enfermedad degenerativa articular | K31: =_xlfn.XLOOKUP($I31,RazónMuerte!$A:$A,RazónMuerte!C:C,"",0) -> 0 | L31: =_xlfn.XLOOKUP($I31,RazónMuerte!$A:$A,RazónMuerte!D:D,"",0) -> No fatal injury (chronic/medical)
A32: 8-FEBRERO-2024 | B32: =LEFT(A32,FIND("-",A32)-1) -> 8 | C32: =MID(A32,FIND("-",A32)+1,FIND("-",A32,FIND("-",A32)+1)-FIND("-",A32)-1) -> FEBRERO | D32: 45325 | E32: 45330 | F32: CARMEN ANITA | G32: =(E32-D32)*24 -> 120 | H32: INDIAN SENSE | I32: ARTRITIS SEVERA | J32: =_xlfn.XLOOKUP($I32,RazónMuerte!$A:$A,RazónMuerte!B:B,"",0) -> Enfermedad degenerativa articular | K32: =_xlfn.XLOOKUP($I32,RazónMuerte!$A:$A,RazónMuerte!C:C,"",0) -> 0 | L32: =_xlfn.XLOOKUP($I32,RazónMuerte!$A:$A,RazónMuerte!D:D,"",0) -> No fatal injury (chronic/medical)
A33: 9-FEBRERO-2024 | B33: =LEFT(A33,FIND("-",A33)-1) -> 9 | C33: =MID(A33,FIND("-",A33)+1,FIND("-",A33,FIND("-",A33)+1)-FIND("-",A33)-1) -> FEBRERO | D33: 44896 | E33: 45331 | F33: LIDIEL | G33: =(E33-D33)*24 -> 10440 | H33: EL MONITOR | I33: Artritis severa menudillo izquierdo delantero | J33: =_xlfn.XLOOKUP($I33,RazónMuerte!$A:$A,RazónMuerte!B:B,"",0) -> Enfermedad degenerativa articular | K33: =_xlfn.XLOOKUP($I33,RazónMuerte!$A:$A,RazónMuerte!C:C,"",0) -> 0 | L33: =_xlfn.XLOOKUP($I33,RazónMuerte!$A:$A,RazónMuerte!D:D,"",0) -> No fatal injury (chronic/medical)
A34: 12-FEBRERO-2024 | B34: =LEFT(A34,FIND("-",A34)-1) -> 12 | C34: =MID(A34,FIND("-",A34)+1,FIND("-",A34,FIND("-",A34)+1)-FIND("-",A34)-1) -> FEBRERO | D34: 45332 | E34: 45334 | F34: V.G.O | G34: =(E34-D34)*24 -> 48 | H34: IAN P.R. | I34: FRACTURA AMBAS RODILLAS | J34: =_xlfn.XLOOKUP($I34,RazónMuerte!$A:$A,RazónMuerte!B:B,"",0) -> Fractura ósea | K34: =_xlfn.XLOOKUP($I34,RazónMuerte!$A:$A,RazónMuerte!C:C,"",0) -> Rodilla / Carpal | L34: =_xlfn.XLOOKUP($I34,RazónMuerte!$A:$A,RazónMuerte!D:D,"",0) -> Fatal injury
A35: 13-FEBRERO-2024 | B35: =LEFT(A35,FIND("-",A35)-1) -> 13 | C35: =MID(A35,FIND("-",A35)+1,FIND("-",A35,FIND("-",A35)+1)-FIND("-",A35)-1) -> FEBRERO | E35: 45335 | F35: CENTRAL | G35: =(E35-D35)*24 -> 1088040 | H35: EL TIO BOLO | I35: ARTRITIS SEVERA RODILLA IZQUIERDA | J35: =_xlfn.XLOOKUP($I35,RazónMuerte!$A:$A,RazónMuerte!B:B,"",0) -> Enfermedad degenerativa articular | K35: =_xlfn.XLOOKUP($I35,RazónMuerte!$A:$A,RazónMuerte!C:C,"",0) -> 0 | L35: =_xlfn.XLOOKUP($I35,RazónMuerte!$A:$A,RazónMuerte!D:D,"",0) -> Fatal injury
A36: 13-FEBRERO-2024 | B36: =LEFT(A36,FIND("-",A36)-1) -> 13 | C36: =MID(A36,FIND("-",A36)+1,FIND("-",A36,FIND("-",A36)+1)-FIND("-",A36)-1) -> FEBRERO | D36: 45324 | E36: 45335 | F36: DIVINO NINO | G36: =(E36-D36)*24 -> 264 | H36: EL MAPA | I36: TENDON BREAKDOWN RF LEG | J36: =_xlfn.XLOOKUP($I36,RazónMuerte!$A:$A,RazónMuerte!B:B,"",0) -> Lesión de ligamentos/tendones | K36: =_xlfn.XLOOKUP($I36,RazónMuerte!$A:$A,RazónMuerte!C:C,"",0) -> 0 | L36: =_xlfn.XLOOKUP($I36,RazónMuerte!$A:$A,RazónMuerte!D:D,"",0) -> No clasificado
A37: 13-FEBRERO-2024 | B37: =LEFT(A37,FIND("-",A37)-1) -> 13 | C37: =MID(A37,FIND("-",A37)+1,FIND("-",A37,FIND("-",A37)+1)-FIND("-",A37)-1) -> FEBRERO | D37: 45333 | E37: 45335 | F37: DESAFIO | G37: =(E37-D37)*24 -> 48 | H37: SPEEDY D | I37: FRACTURA SESAMOIDE PATA DERECHA DELANTERA | J37: =_xlfn.XLOOKUP($I37,RazónMuerte!$A:$A,RazónMuerte!B:B,"",0) -> Fractura ósea | K37: =_xlfn.XLOOKUP($I37,RazónMuerte!$A:$A,RazónMuerte!C:C,"",0) -> Sesamoideo | L37: =_xlfn.XLOOKUP($I37,RazónMuerte!$A:$A,RazónMuerte!D:D,"",0) -> Fatal injury
A38: 13-FEBRERO-2024 | B38: =LEFT(A38,FIND("-",A38)-1) -> 13 | C38: =MID(A38,FIND("-",A38)+1,FIND("-",A38,FIND("-",A38)+1)-FIND("-",A38)-1) -> FEBRERO | D38: 45292 | E38: 45335 | F38: ALAMO | G38: =(E38-D38)*24 -> 1032 | H38: CLEMENTE BORICUA | I38: FRACTURA AMBAS RODILLAS | J38: =_xlfn.XLOOKUP($I38,RazónMuerte!$A:$A,RazónMuerte!B:B,"",0) -> Fractura ósea | K38: =_xlfn.XLOOKUP($I38,RazónMuerte!$A:$A,RazónMuerte!C:C,"",0) -> Rodilla / Carpal | L38: =_xlfn.XLOOKUP($I38,RazónMuerte!$A:$A,RazónMuerte!D:D,"",0) -> Fatal injury
A39: 14-FEBRERO-2024 | B39: =LEFT(A39,FIND("-",A39)-1) -> 14 | C39: =MID(A39,FIND("-",A39)+1,FIND("-",A39,FIND("-",A39)+1)-FIND("-",A39)-1) -> FEBRERO | D39: 45305 | E39: 45336 | F39: SILENT | G39: =(E39-D39)*24 -> 744 | H39: RECOMPENSADO | I39: Artritis severa rodilla derecha | J39: =_xlfn.XLOOKUP($I39,RazónMuerte!$A:$A,RazónMuerte!B:B,"",0) -> Enfermedad degenerativa articular | K39: =_xlfn.XLOOKUP($I39,RazónMuerte!$A:$A,RazónMuerte!C:C,"",0) -> 0 | L39: =_xlfn.XLOOKUP($I39,RazónMuerte!$A:$A,RazónMuerte!D:D,"",0) -> Fatal injury
A40: 16-FEBRERO-2024 | B40: =LEFT(A40,FIND("-",A40)-1) -> 16 | C40: =MID(A40,FIND("-",A40)+1,FIND("-",A40,FIND("-",A40)+1)-FIND("-",A40)-1) -> FEBRERO | D40: 45337 | E40: 45338 | F40: DC | G40: =(E40-D40)*24 -> 24 | H40: EL DICTADOR | I40: Fractura sesamoide derecho delantero | J40: =_xlfn.XLOOKUP($I40,RazónMuerte!$A:$A,RazónMuerte!B:B,"",0) -> Fractura ósea | K40: =_xlfn.XLOOKUP($I40,RazónMuerte!$A:$A,RazónMuerte!C:C,"",0) -> Sesamoideo | L40: =_xlfn.XLOOKUP($I40,RazónMuerte!$A:$A,RazónMuerte!D:D,"",0) -> Fatal injury
...

Sheet 2025 data
A1: FECHA | B1: día | C1: Mes | D1: Last Race Date (desde Equibase) | E1: Death Date | F1: ESTABLO | G1: Horas transcurridas | H1: CABALLO | I1: RAZON | J1: Categoría | K1: Tipo de fractura | L1: Fatal injury | M1: Registrado/Compitió?
A2: 12-MARZO-2025 | B2: =LEFT(A2,FIND("-",A2)-1) -> 12 | C2: =MID(A2,FIND("-",A2)+1,FIND("-",A2,FIND("-",A2)+1)-FIND("-",A2)-1) -> MARZO | D2: 42910 | E2: 45728 | F2: CTA | G2: 67632 | H2: CRUISES CREEK | I2: Cólico. Colon desplazado. | J2: =_xlfn.XLOOKUP($I2,RazónMuerte!$A:$A,RazónMuerte!B:B,"",0) -> Otras / No especificada | K2: =_xlfn.XLOOKUP($I2,RazónMuerte!$A:$A,RazónMuerte!C:C,"",0) -> 0 | L2: =_xlfn.XLOOKUP($I2,RazónMuerte!$A:$A,RazónMuerte!D:D,"",0) -> No clasificado | M2: Si
A3: 31-OCTUBRE-2025 | B3: =LEFT(A3,FIND("-",A3)-1) -> 31 | C3: =MID(A3,FIND("-",A3)+1,FIND("-",A3,FIND("-",A3)+1)-FIND("-",A3)-1) -> OCTUBRE | D3: 45169 | E3: 45961 | F3: SONATA | G3: 19008 | H3: TEMPORERA | I3: LAMINITIS CRONICA | J3: =_xlfn.XLOOKUP($I3,RazónMuerte!$A:$A,RazónMuerte!B:B,"",0) -> Otras / No especificada | K3: =_xlfn.XLOOKUP($I3,RazónMuerte!$A:$A,RazónMuerte!C:C,"",0) -> 0 | L3: =_xlfn.XLOOKUP($I3,RazónMuerte!$A:$A,RazónMuerte!D:D,"",0) -> No clasificado | M3: Si
A4: 13-AGOSTO-2025 | B4: =LEFT(A4,FIND("-",A4)-1) -> 13 | C4: =MID(A4,FIND("-",A4)+1,FIND("-",A4,FIND("-",A4)+1)-FIND("-",A4)-1) -> AGOSTO | D4: 45227 | E4: 45882 | F4: JI DIAMOND | G4: 15720 | H4: EL GALLOLFO | I4: Laminitis en ambas manos/Múltiples fracturas en ambas rodillas L>R. | J4: =_xlfn.XLOOKUP($I4,RazónMuerte!$A:$A,RazónMuerte!B:B,"",0) -> Fractura ósea | K4: =_xlfn.XLOOKUP($I4,RazónMuerte!$A:$A,RazónMuerte!C:C,"",0) -> Rodilla / Carpal | L4: =_xlfn.XLOOKUP($I4,RazónMuerte!$A:$A,RazónMuerte!D:D,"",0) -> Fatal injury | M4: Si
A5: 15-SEPTIEMBRE-2025 | B5: =LEFT(A5,FIND("-",A5)-1) -> 15 | C5: =MID(A5,FIND("-",A5)+1,FIND("-",A5,FIND("-",A5)+1)-FIND("-",A5)-1) -> SEPTIEMBRE | D5: 45326 | E5: 45915 | F5: G.C.A. | G5: 14136 | H5: MASTERY ASHLEY JHU | I5: Chronic infected wound on medial aspect of L front fetlock. | J5: =_xlfn.XLOOKUP($I5,RazónMuerte!$A:$A,RazónMuerte!B:B,"",0) -> Otras / No especificada | K5: =_xlfn.XLOOKUP($I5,RazónMuerte!$A:$A,RazónMuerte!C:C,"",0) -> 0 | L5: =_xlfn.XLOOKUP($I5,RazónMuerte!$A:$A,RazónMuerte!D:D,"",0) -> Fatal injury | M5: Si
A6: 28-JULIO-2025 | B6: =LEFT(A6,FIND("-",A6)-1) -> 28 | C6: =MID(A6,FIND("-",A6)+1,FIND("-",A6,FIND("-",A6)+1)-FIND("-",A6)-1) -> JULIO | D6: 45345 | E6: 45866 | F6: CANITO | G6: 12504 | H6: CONSULADO | I6: Cólico. | J6: =_xlfn.XLOOKUP($I6,RazónMuerte!$A:$A,RazónMuerte!B:B,"",0) -> Otras / No especificada | K6: =_xlfn.XLOOKUP($I6,RazónMuerte!$A:$A,RazónMuerte!C:C,"",0) -> 0 | L6: =_xlfn.XLOOKUP($I6,RazónMuerte!$A:$A,RazónMuerte!D:D,"",0) -> No clasificado | M6: Si
A7: 15-JULIO-2025 | B7: =LEFT(A7,FIND("-",A7)-1) -> 15 | C7: =MID(A7,FIND("-",A7)+1,FIND("-",A7,FIND("-",A7)+1)-FIND("-",A7)-1) -> JULIO | D7: 45402 | E7: 45853 | F7: E.R.V. ENTERPRISES | G7: 10824 | H7: ÁGUILA BLANCA | I7: Severe tenosynovitis of RF limb (Referido PRHOA) | J7: =_xlfn.XLOOKUP($I7,RazónMuerte!$A:$A,RazónMuerte!B:B,"",0) -> Otras / No especificada | K7: =_xlfn.XLOOKUP($I7,RazónMuerte!$A:$A,RazónMuerte!C:C,"",0) -> 0 | L7: =_xlfn.XLOOKUP($I7,RazónMuerte!$A:$A,RazónMuerte!D:D,"",0) -> No clasificado | M7: Si
